2013-07-15 16:56:16
Traceback (most recent call last):
  File "./sftp/threads.py", line 16, in run_with_except_hook
  File "./sftp/threads.py", line 101, in handler
  File "./sftp/commands.py", line 264, in run
  File "./sftp/commands.py", line 403, in do_operation
  File "./sftp/file_transfer.py", line 25, in handler
  File "./sftp/ftp_transport.py", line 734, in put
NotFoundError: Folder not found
2013-07-15 16:57:04
Traceback (most recent call last):
  File "./sftp/threads.py", line 16, in run_with_except_hook
  File "./sftp/threads.py", line 101, in handler
  File "./sftp/commands.py", line 264, in run
  File "./sftp/commands.py", line 403, in do_operation
  File "./sftp/file_transfer.py", line 25, in handler
  File "./sftp/ftp_transport.py", line 734, in put
PermissionError: oop already exists
